Workbook

Sheet Close seats
A1: AC no | B1: Assembly seat | C1: Lok Sabha seat | D1: Winner party | E1: Alliance | F1: Margin (votes) | G1: Margin % | H1: Voters added | I1: Added ÷ margin | J1: Added is actual (RTI)?
A2: 114 | B2: Malegaon Central | C2: Dhule | D2: AIMIM | E2: Other | F2: ='Assembly seats'!J115 -> 162 | G2: ='Assembly seats'!K115 -> 0.00067457558 | H2: ='Assembly seats'!P115 -> 18483 | I2: =H2/F2 -> 114.09259 | J2: No (estimated)
A3: 151 | B3: Belapur | C3: Thane | D3: BJP | E3: Mahayuti | F3: ='Assembly seats'!J152 -> 377 | G3: ='Assembly seats'!K152 -> 0.0016023666 | H3: ='Assembly seats'!P152 -> 28220 | I3: =H3/F3 -> 74.854111 | J3: No (estimated)
A4: 62 | B4: Sakoli | C4: Bhandara-Gondiya | D4: INC | E4: MVA | F4: ='Assembly seats'!J63 -> 208 | G4: ='Assembly seats'!K63 -> 0.00088275487 | H4: ='Assembly seats'!P63 -> 7944 | I4: =H4/F4 -> 38.192308 | J4: No (estimated)
A5: 196 | B5: Ambegaon | C5: Shirur | D5: NCP | E5: Mahayuti | F5: ='Assembly seats'!J197 -> 1523 | G5: ='Assembly seats'!K197 -> 0.0068444824 | H5: ='Assembly seats'!P197 -> 20483 | I5: =H5/F5 -> 13.449114 | J5: No (estimated)
A6: 22 | B6: Buldhana | C6: Buldhana | D6: SHS | E6: Mahayuti | F6: ='Assembly seats'!J23 -> 841 | G6: ='Assembly seats'!K23 -> 0.0043178469 | H6: ='Assembly seats'!P23 -> 10549 | I6: =H6/F6 -> 12.543401 | J6: No (estimated)
A7: 135 | B7: Shahapur (ST) | C7: Bhiwandi | D7: NCP | E7: Mahayuti | F7: ='Assembly seats'!J136 -> 1672 | G7: ='Assembly seats'!K136 -> 0.008085341 | H7: ='Assembly seats'!P136 -> 20704 | I7: =H7/F7 -> 12.382775 | J7: No (estimated)
A8: 30 | B8: Akola West | C8: Akola | D8: INC | E8: MVA | F8: ='Assembly seats'!J31 -> 1283 | G8: ='Assembly seats'!K31 -> 0.0062488433 | H8: ='Assembly seats'!P31 -> 12777 | I8: =H8/F8 -> 9.9586906 | J8: No (estimated)
A9: 227 | B9: Karjat Jamkhed | C9: Ahmednagar | D9: NCP(SP) | E9: MVA | F9: ='Assembly seats'!J228 -> 1243 | G9: ='Assembly seats'!K228 -> 0.0047253374 | H9: ='Assembly seats'!P228 -> 11948 | I9: =H9/F9 -> 9.6122285 | J9: No (estimated)
A10: 4 | B10: Navapur (ST) | C10: Nandurbar | D10: INC | E10: MVA | F10: ='Assembly seats'!J5 -> 1121 | G10: ='Assembly seats'!K5 -> 0.0046477881 | H10: ='Assembly seats'!P5 -> 9828 | I10: =H10/F10 -> 8.7671722 | J10: No (estimated)
A11: 224 | B11: Parner | C11: Ahmednagar | D11: NCP | E11: Mahayuti | F11: ='Assembly seats'!J225 -> 1526 | G11: ='Assembly seats'!K225 -> 0.0061300404 | H11: ='Assembly seats'!P225 -> 12053 | I11: =H11/F11 -> 7.8984273 | J11: No (estimated)
A12: 133 | B12: Vasai | C12: Palghar | D12: BJP | E12: Mahayuti | F12: ='Assembly seats'!J134 -> 3153 | G12: ='Assembly seats'!K134 -> 0.014384124 | H12: ='Assembly seats'!P134 -> 22212 | I12: =H12/F12 -> 7.0447193 | J12: No (estimated)
A13: 109 | B13: Aurangabad East | C13: Aurangabad | D13: BJP | E13: Mahayuti | F13: ='Assembly seats'!J110 -> 2161 | G13: ='Assembly seats'!K110 -> 0.0099785745 | H13: ='Assembly seats'!P110 -> 14689 | I13: =H13/F13 -> 6.7973161 | J13: No (estimated)
A14: 158 | B14: Jogeshwari East | C14: Mumbai North West | D14: SS(UBT) | E14: MVA | F14: ='Assembly seats'!J159 -> 1541 | G14: ='Assembly seats'!K159 -> 0.0086646537 | H14: ='Assembly seats'!P159 -> 10417 | I14: =H14/F14 -> 6.7598962 | J14: No (estimated)
A15: 275 | B15: Karvir | C15: Kolhapur | D15: SHS | E15: Mahayuti | F15: ='Assembly seats'!J276 -> 1976 | G15: ='Assembly seats'!K276 -> 0.0070875434 | H15: ='Assembly seats'!P276 -> 12739 | I15: =H15/F15 -> 6.4468623 | J15: No (estimated)
A16: 164 | B16: Versova | C16: Mumbai North West | D16: SS(UBT) | E16: MVA | F16: ='Assembly seats'!J165 -> 1600 | G16: ='Assembly seats'!K165 -> 0.010816585 | H16: ='Assembly seats'!P165 -> 9988 | I16: =H16/F16 -> 6.2425 | J16: No (estimated)
A17: 104 | B17: Sillod | C17: Jalna | D17: SHS | E17: Mahayuti | F17: ='Assembly seats'!J105 -> 2420 | G17: ='Assembly seats'!K105 -> 0.0083654528 | H17: ='Assembly seats'!P105 -> 14917 | I17: =H17/F17 -> 6.1640496 | J17: No (estimated)
A18: 208 | B18: Vadgaon Sheri | C18: Pune | D18: NCP(SP) | E18: MVA | F18: ='Assembly seats'!J209 -> 4710 | G18: ='Assembly seats'!K209 -> 0.016583981 | H18: ='Assembly seats'!P209 -> 27249 | I18: =H18/F18 -> 5.7853503 | J18: No (estimated)
A19: 213 | B19: Hadapsar | C19: Shirur | D19: NCP | E19: Mahayuti | F19: ='Assembly seats'!J214 -> 7122 | G19: ='Assembly seats'!K214 -> 0.022433121 | H19: ='Assembly seats'!P214 -> 40781 | I19: =H19/F19 -> 5.7260601 | J19: No (estimated)
A20: 243 | B20: Paranda | C20: Osmanabad | D20: SHS | E20: Mahayuti | F20: ='Assembly seats'!J244 -> 1509 | G20: ='Assembly seats'!K244 -> 0.0064565817 | H20: ='Assembly seats'!P244 -> 8582 | I20: =H20/F20 -> 5.6872101 | J20: No (estimated)
A21: 232 | B21: Kaij (SC) | C21: Beed | D21: BJP | E21: Mahayuti | F21: ='Assembly seats'!J233 -> 2687 | G21: ='Assembly seats'!K233 -> 0.010805181 | H21: ='Assembly seats'!P233 -> 14825 | I21: =H21/F21 -> 5.5173055 | J21: No (estimated)
A22: 100 | B22: Ghansawangi | C22: Parbhani | D22: SHS | E22: Mahayuti | F22: ='Assembly seats'!J101 -> 2309 | G22: ='Assembly seats'!K101 -> 0.0090089739 | H22: ='Assembly seats'!P101 -> 12533 | I22: =H22/F22 -> 5.4278909 | J22: No (estimated)
A23: 56 | B23: Nagpur West | C23: Nagpur | D23: INC | E23: MVA | F23: ='Assembly seats'!J57 -> 5824 | G23: ='Assembly seats'!K57 -> 0.026535206 | H23: ='Assembly seats'!P57 -> 26031 | I23: =H23/F23 -> 4.4696085 | J23: No (estimated)
A24: 87 | B24: Nanded South | C24: Nanded | D24: SHS | E24: Mahayuti | F24: ='Assembly seats'!J88 -> 2132 | G24: ='Assembly seats'!K88 -> 0.010436911 | H24: ='Assembly seats'!P88 -> 9413 | I24: =H24/F24 -> 4.4151032 | J24: No (estimated)
A25: 128 | B25: Dahanu (ST) | C25: Palghar | D25: CPI(M) | E25: Other | F25: ='Assembly seats'!J129 -> 5133 | G25: ='Assembly seats'!K129 -> 0.023144662 | H25: ='Assembly seats'!P129 -> 18867 | I25: =H25/F25 -> 3.6756283 | J25: No (estimated)
A26: 1 | B26: Akkalkuwa (ST) | C26: Nandurbar | D26: SHS | E26: Mahayuti | F26: ='Assembly seats'!J2 -> 2904 | G26: ='Assembly seats'!K2 -> 0.012614953 | H26: ='Assembly seats'!P2 -> 10614 | I26: =H26/F26 -> 3.6549587 | J26: No (estimated)
A27: 77 | B27: Ralegaon (ST) | C27: Yavatmal-Washim | D27: BJP | E27: Mahayuti | F27: ='Assembly seats'!J78 -> 2812 | G27: ='Assembly seats'!K78 -> 0.013125712 | H27: ='Assembly seats'!P78 -> 10135 | I27: =H27/F27 -> 3.6041963 | J27: No (estimated)
A28: 70 | B28: Rajura | C28: Chandrapur | D28: BJP | E28: Mahayuti | F28: ='Assembly seats'!J71 -> 3054 | G28: ='Assembly seats'!K71 -> 0.01279307 | H28: ='Assembly seats'!P71 -> 10905 | I28: =H28/F28 -> 3.5707269 | J28: No (estimated)
A29: 38 | B29: Amravati | C29: Amravati | D29: NCP | E29: Mahayuti | F29: ='Assembly seats'!J39 -> 5496 | G29: ='Assembly seats'!K39 -> 0.026085471 | H29: ='Assembly seats'!P39 -> 19600 | I29: =H29/F29 -> 3.56623 | J29: No (estimated)
A30: 189 | B30: Karjat | C30: Maval | D30: SHS | E30: Mahayuti | F30: ='Assembly seats'!J190 -> 5694 | G30: ='Assembly seats'!K190 -> 0.023725099 | H30: ='Assembly seats'!P190 -> 19591 | I30: =H30/F30 -> 3.4406393 | J30: No (estimated)
A31: 181 | B31: Mahim | C31: Mumbai South Central | D31: SS(UBT) | E31: MVA | F31: ='Assembly seats'!J182 -> 1316 | G31: ='Assembly seats'!K182 -> 0.00977719 | H31: ='Assembly seats'!P182 -> 4519 | I31: =H31/F31 -> 3.4338906 | J31: No (estimated)
A32: 23 | B32: Chikhli | C32: Buldhana | D32: BJP | E32: Mahayuti | F32: ='Assembly seats'!J24 -> 3201 | G32: ='Assembly seats'!K24 -> 0.014326699 | H32: ='Assembly seats'!P24 -> 10502 | I32: =H32/F32 -> 3.2808497 | J32: No (estimated)
A33: 95 | B33: Jintur | C33: Parbhani | D33: BJP | E33: Mahayuti | F33: ='Assembly seats'!J96 -> 4516 | G33: ='Assembly seats'!K96 -> 0.015335715 | H33: ='Assembly seats'!P96 -> 14734 | I33: =H33/F33 -> 3.2626218 | J33: No (estimated)
A34: 190 | B34: Uran | C34: Maval | D34: BJP | E34: Mahayuti | F34: ='Assembly seats'!J191 -> 6512 | G34: ='Assembly seats'!K191 -> 0.024708971 | H34: ='Assembly seats'!P191 -> 21027 | I34: =H34/F34 -> 3.2289619 | J34: No (estimated)
A35: 195 | B35: Junnar | C35: Shirur | D35: IND | E35: Other | F35: ='Assembly seats'!J196 -> 6664 | G35: ='Assembly seats'!K196 -> 0.029460524 | H35: ='Assembly seats'!P196 -> 21233 | I35: =H35/F35 -> 3.1862245 | J35: No (estimated)
A36: 86 | B36: Nanded North | C36: Nanded | D36: SHS | E36: Mahayuti | F36: ='Assembly seats'!J87 -> 3502 | G36: ='Assembly seats'!K87 -> 0.015863094 | H36: ='Assembly seats'!P87 -> 10663 | I36: =H36/F36 -> 3.0448315 | J36: No (estimated)
A37: 111 | B37: Gangapur | C37: Aurangabad | D37: BJP | E37: Mahayuti | F37: ='Assembly seats'!J112 -> 5015 | G37: ='Assembly seats'!K112 -> 0.018601287 | H37: ='Assembly seats'!P112 -> 15109 | I37: =H37/F37 -> 3.0127617 | J37: No (estimated)
A38: 230 | B38: Beed | C38: Beed | D38: NCP(SP) | E38: MVA | F38: ='Assembly seats'!J231 -> 5324 | G38: ='Assembly seats'!K231 -> 0.021934288 | H38: ='Assembly seats'!P231 -> 14706 | I38: =H38/F38 -> 2.7622089 | J38: No (estimated)
A39: 99 | B39: Partur | C39: Parbhani | D39: BJP | E39: Mahayuti | F39: ='Assembly seats'!J100 -> 4740 | G39: ='Assembly seats'!K100 -> 0.020721855 | H39: ='Assembly seats'!P100 -> 12262 | I39: =H39/F39 -> 2.5869198 | J39: No (estimated)
A40: 252 | B40: Pandharpur | C40: Solapur | D40: BJP | E40: Mahayuti | F40: ='Assembly seats'!J253 -> 8430 | G40: ='Assembly seats'!K253 -> 0.032131178 | H40: ='Assembly seats'!P253 -> 20281 | I40: =H40/F40 -> 2.4058126 | J40: No (estimated)
...

Sheet Lok Sabha seats
A1: Lok Sabha seat | B1: Electors, LS May 2024 (ECI) | C1: Electors, VS Nov 2024 (sum of 6 ACs) | D1: Net change | E1: Change % | F1: Mahayuti wins (of 6) | G1: MVA wins (of 6) | H1: Avg winning margin %
A2: Ahmednagar | B2: 1981866 | C2: =SUMIFS('Assembly seats'!$N:$N,'Assembly seats'!$D:$D,A2) -> 2052474 | D2: =C2-B2 -> 70608 | E2: =D2/B2 -> 0.03562703 | F2: =COUNTIFS('Assembly seats'!$D:$D,A2,'Assembly seats'!$F:$F,"Mahayuti") -> 5 | G2: =COUNTIFS('Assembly seats'!$D:$D,A2,'Assembly seats'!$F:$F,"MVA") -> 1 | H2: =AVERAGEIFS('Assembly seats'!$K:$K,'Assembly seats'!$D:$D,A2) -> 0.094250159
A3: Akola | B3: 1890814 | C3: =SUMIFS('Assembly seats'!$N:$N,'Assembly seats'!$D:$D,A3) -> 1962286 | D3: =C3-B3 -> 71472 | E3: =D3/B3 -> 0.037799593 | F3: =COUNTIFS('Assembly seats'!$D:$D,A3,'Assembly seats'!$F:$F,"Mahayuti") -> 3 | G3: =COUNTIFS('Assembly seats'!$D:$D,A3,'Assembly seats'!$F:$F,"MVA") -> 3 | H3: =AVERAGEIFS('Assembly seats'!$K:$K,'Assembly seats'!$D:$D,A3) -> 0.095595643
A4: Amravati | B4: 1836078 | C4: =SUMIFS('Assembly seats'!$N:$N,'Assembly seats'!$D:$D,A4) -> 1937493 | D4: =C4-B4 -> 101415 | E4: =D4/B4 -> 0.055234582 | F4: =COUNTIFS('Assembly seats'!$D:$D,A4,'Assembly seats'!$F:$F,"Mahayuti") -> 4 | G4: =COUNTIFS('Assembly seats'!$D:$D,A4,'Assembly seats'!$F:$F,"MVA") -> 1 | H4: =AVERAGEIFS('Assembly seats'!$K:$K,'Assembly seats'!$D:$D,A4) -> 0.16856928
A5: Aurangabad | B5: 2059710 | C5: =SUMIFS('Assembly seats'!$N:$N,'Assembly seats'!$D:$D,A5) -> 2148710 | D5: =C5-B5 -> 89000 | E5: =D5/B5 -> 0.043209966 | F5: =COUNTIFS('Assembly seats'!$D:$D,A5,'Assembly seats'!$F:$F,"Mahayuti") -> 6 | G5: =COUNTIFS('Assembly seats'!$D:$D,A5,'Assembly seats'!$F:$F,"MVA") -> 0 | H5: =AVERAGEIFS('Assembly seats'!$K:$K,'Assembly seats'!$D:$D,A5) -> 0.063239803
A6: Baramati | B6: 2372668 | C6: =SUMIFS('Assembly seats'!$N:$N,'Assembly seats'!$D:$D,A6) -> 2512204 | D6: =C6-B6 -> 139536 | E6: =D6/B6 -> 0.058809745 | F6: =COUNTIFS('Assembly seats'!$D:$D,A6,'Assembly seats'!$F:$F,"Mahayuti") -> 6 | G6: =COUNTIFS('Assembly seats'!$D:$D,A6,'Assembly seats'!$F:$F,"MVA") -> 0 | H6: =AVERAGEIFS('Assembly seats'!$K:$K,'Assembly seats'!$D:$D,A6) -> 0.13543221
A7: Beed | B7: 2142547 | C7: =SUMIFS('Assembly seats'!$N:$N,'Assembly seats'!$D:$D,A7) -> 2227844 | D7: =C7-B7 -> 85297 | E7: =D7/B7 -> 0.039811029 | F7: =COUNTIFS('Assembly seats'!$D:$D,A7,'Assembly seats'!$F:$F,"Mahayuti") -> 5 | G7: =COUNTIFS('Assembly seats'!$D:$D,A7,'Assembly seats'!$F:$F,"MVA") -> 1 | H7: =AVERAGEIFS('Assembly seats'!$K:$K,'Assembly seats'!$D:$D,A7) -> 0.17137018
A8: Bhandara-Gondiya | B8: 1827188 | C8: =SUMIFS('Assembly seats'!$N:$N,'Assembly seats'!$D:$D,A8) -> 1872471 | D8: =C8-B8 -> 45283 | E8: =D8/B8 -> 0.02478289 | F8: =COUNTIFS('Assembly seats'!$D:$D,A8,'Assembly seats'!$F:$F,"Mahayuti") -> 5 | G8: =COUNTIFS('Assembly seats'!$D:$D,A8,'Assembly seats'!$F:$F,"MVA") -> 1 | H8: =AVERAGEIFS('Assembly seats'!$K:$K,'Assembly seats'!$D:$D,A8) -> 0.16960755
A9: Bhiwandi | B9: 2087244 | C9: =SUMIFS('Assembly seats'!$N:$N,'Assembly seats'!$D:$D,A9) -> 2247087 | D9: =C9-B9 -> 159843 | E9: =D9/B9 -> 0.076580888 | F9: =COUNTIFS('Assembly seats'!$D:$D,A9,'Assembly seats'!$F:$F,"Mahayuti") -> 5 | G9: =COUNTIFS('Assembly seats'!$D:$D,A9,'Assembly seats'!$F:$F,"MVA") -> 0 | H9: =AVERAGEIFS('Assembly seats'!$K:$K,'Assembly seats'!$D:$D,A9) -> 0.17150588
A10: Buldhana | B10: 1782700 | C10: =SUMIFS('Assembly seats'!$N:$N,'Assembly seats'!$D:$D,A10) -> 1846115 | D10: =C10-B10 -> 63415 | E10: =D10/B10 -> 0.035572446 | F10: =COUNTIFS('Assembly seats'!$D:$D,A10,'Assembly seats'!$F:$F,"Mahayuti") -> 5 | G10: =COUNTIFS('Assembly seats'!$D:$D,A10,'Assembly seats'!$F:$F,"MVA") -> 1 | H10: =AVERAGEIFS('Assembly seats'!$K:$K,'Assembly seats'!$D:$D,A10) -> 0.042559093
A11: Chandrapur | B11: 1837906 | C11: =SUMIFS('Assembly seats'!$N:$N,'Assembly seats'!$D:$D,A11) -> 1901657 | D11: =C11-B11 -> 63751 | E11: =D11/B11 -> 0.034686758 | F11: =COUNTIFS('Assembly seats'!$D:$D,A11,'Assembly seats'!$F:$F,"Mahayuti") -> 5 | G11: =COUNTIFS('Assembly seats'!$D:$D,A11,'Assembly seats'!$F:$F,"MVA") -> 1 | H11: =AVERAGEIFS('Assembly seats'!$K:$K,'Assembly seats'!$D:$D,A11) -> 0.084645071
A12: Dhule | B12: 2022061 | C12: =SUMIFS('Assembly seats'!$N:$N,'Assembly seats'!$D:$D,A12) -> 2137330 | D12: =C12-B12 -> 115269 | E12: =D12/B12 -> 0.057005699 | F12: =COUNTIFS('Assembly seats'!$D:$D,A12,'Assembly seats'!$F:$F,"Mahayuti") -> 5 | G12: =COUNTIFS('Assembly seats'!$D:$D,A12,'Assembly seats'!$F:$F,"MVA") -> 0 | H12: =AVERAGEIFS('Assembly seats'!$K:$K,'Assembly seats'!$D:$D,A12) -> 0.31704728
A13: Dindori | B13: 1853387 | C13: =SUMIFS('Assembly seats'!$N:$N,'Assembly seats'!$D:$D,A13) -> 1908487 | D13: =C13-B13 -> 55100 | E13: =D13/B13 -> 0.029729355 | F13: =COUNTIFS('Assembly seats'!$D:$D,A13,'Assembly seats'!$F:$F,"Mahayuti") -> 6 | G13: =COUNTIFS('Assembly seats'!$D:$D,A13,'Assembly seats'!$F:$F,"MVA") -> 0 | H13: =AVERAGEIFS('Assembly seats'!$K:$K,'Assembly seats'!$D:$D,A13) -> 0.16954521
... A49: Yavatmal-Washim | B49: 1940916 | C49: =SUMIFS('Assembly seats'!$N:$N,'Assembly seats'!$D:$D,A49) -> 2011704 | D49: =C49-B49 -> 70788 | E49: =D49/B49 -> 0.036471439 | F49: =COUNTIFS('Assembly seats'!$D:$D,A49,'Assembly seats'!$F:$F,"Mahayuti") -> 5 | G49: =COUNTIFS('Assembly seats'!$D:$D,A49,'Assembly seats'!$F:$F,"MVA") -> 1 | H49: =AVERAGEIFS('Assembly seats'!$K:$K,'Assembly seats'!$D:$D,A49) -> 0.14018227
A50: Maharashtra total | B50: =SUM(B2:B49) -> 92943890 | C50: =SUM(C2:C49) -> 97025119 | D50: =SUM(D2:D49) -> 4081229 | E50: =D50/B50 -> 0.043910676 | F50: =SUM(F2:F49) -> 230 | G50: =SUM(G2:G49) -> 46

Sheet Assembly seats
A1: AC no | B1: Assembly seat | C1: District | D1: Lok Sabha seat | E1: Winner party | F1: Alliance | G1: Winner votes | H1: Runner-up votes | I1: Total votes polled | J1: Margin (votes) | K1: Margin % of votes polled | L1: Turnout | M1: Lok Sabha seat elector growth % | N1: Electors, 30 Oct 2024 (CEO) | O1: Actual net added (RTI) | P1: Voters added (used) | Q1: Added ÷ margin | R1: Added > margin? | S1: Added × turnout > margin? | T1: Votes source
A2: 1 | B2: Akkalkuwa (ST) | C2: Nandurbar | D2: Nandurbar | E2: SHS | F2: Mahayuti | G2: 72629 | H2: 69725 | I2: 230203 | J2: =G2-H2 -> 2904 | K2: =J2/I2 -> 0.012614953 | L2: =I2/N2 -> 0.72064776 | M2: =INDEX('Lok Sabha seats'!$E:$E,MATCH(D2,'Lok Sabha seats'!$A:$A,0)) -> 0.034368914 | N2: 319439 | P2: =IF(O2<>"",O2,ROUND(N2*M2/(1+M2),0)) -> 10614 | Q2: =P2/J2 -> 3.6549587 | R2: =IF(P2>J2,"Yes","No") -> Yes | S2: =IF(P2*L2>J2,"Yes","No") -> Yes | T2: Wikipedia (reproducing ECI)
A3: 2 | B3: Shahada (ST) | C3: Nandurbar | D3: Nandurbar | E3: BJP | F3: Mahayuti | G3: 146839 | H3: 93635 | I3: 245304 | J3: =G3-H3 -> 53204 | K3: =J3/I3 -> 0.21689006 | L3: =I3/N3 -> 0.69562949 | M3: =INDEX('Lok Sabha seats'!$E:$E,MATCH(D3,'Lok Sabha seats'!$A:$A,0)) -> 0.034368914 | N3: 352636 | P3: =IF(O3<>"",O3,ROUND(N3*M3/(1+M3),0)) -> 11717 | Q3: =P3/J3 -> 0.2202278 | R3: =IF(P3>J3,"Yes","No") -> No | S3: =IF(P3*L3>J3,"Yes","No") -> No | T3: Wikipedia (reproducing ECI)
A4: 3 | B4: Nandurbar (ST) | C4: Nandurbar | D4: Nandurbar | E4: BJP | F4: Mahayuti | G4: 155190 | H4: 78943 | I4: 240158 | J4: =G4-H4 -> 76247 | K4: =J4/I4 -> 0.31748682 | L4: =I4/N4 -> 0.67883239 | M4: =INDEX('Lok Sabha seats'!$E:$E,MATCH(D4,'Lok Sabha seats'!$A:$A,0)) -> 0.034368914 | N4: 353781 | P4: =IF(O4<>"",O4,ROUND(N4*M4/(1+M4),0)) -> 11755 | Q4: =P4/J4 -> 0.15417 | R4: =IF(P4>J4,"Yes","No") -> No | S4: =IF(P4*L4>J4,"Yes","No") -> No | T4: Wikipedia (reproducing ECI)
A5: 4 | B5: Navapur (ST) | C5: Nandurbar | D5: Nandurbar | E5: INC | F5: MVA | G5: 87166 | H5: 86045 | I5: 241190 | J5: =G5-H5 -> 1121 | K5: =J5/I5 -> 0.0046477881 | L5: =I5/N5 -> 0.81542061 | M5: =INDEX('Lok Sabha seats'!$E:$E,MATCH(D5,'Lok Sabha seats'!$A:$A,0)) -> 0.034368914 | N5: 295786 | P5: =IF(O5<>"",O5,ROUND(N5*M5/(1+M5),0)) -> 9828 | Q5: =P5/J5 -> 8.7671722 | R5: =IF(P5>J5,"Yes","No") -> Yes | S5: =IF(P5*L5>J5,"Yes","No") -> Yes | T5: Wikipedia (reproducing ECI)
A6: 5 | B6: Sakri (ST) | C6: Dhule | D6: Nandurbar | E6: SHS | F6: Mahayuti | G6: 104649 | H6: 99065 | I6: 242243 | J6: =G6-H6 -> 5584 | K6: =J6/I6 -> 0.023051234 | L6: =I6/N6 -> 0.66294023 | M6: =INDEX('Lok Sabha seats'!$E:$E,MATCH(D6,'Lok Sabha seats'!$A:$A,0)) -> 0.034368914 | N6: 365407 | P6: =IF(O6<>"",O6,ROUND(N6*M6/(1+M6),0)) -> 12141 | Q6: =P6/J6 -> 2.1742479 | R6: =IF(P6>J6,"Yes","No") -> Yes | S6: =IF(P6*L6>J6,"Yes","No") -> Yes | T6: Wikipedia (reproducing ECI)
A7: 6 | B7: Dhule Rural | C7: Dhule | D7: Dhule | E7: BJP | F7: Mahayuti | G7: 170398 | H7: 104078 | I7: 289448 | J7: =G7-H7 -> 66320 | K7: =J7/I7 -> 0.22912578 | L7: =I7/N7 -> 0.70687588 | M7: =INDEX('Lok Sabha seats'!$E:$E,MATCH(D7,'Lok Sabha seats'!$A:$A,0)) -> 0.057005699 | N7: 409475 | P7: =IF(O7<>"",O7,ROUND(N7*M7/(1+M7),0)) -> 22084 | Q7: =P7/J7 -> 0.33299156 | R7: =IF(P7>J7,"Yes","No") -> No | S7: =IF(P7*L7>J7,"Yes","No") -> No | T7: Wikipedia (reproducing ECI)
A8: 7 | B8: Dhule City | C8: Dhule | D8: Dhule | E8: BJP | F8: Mahayuti | G8: 116538 | H8: 70788 | I8: 220382 | J8: =G8-H8 -> 45750 | K8: =J8/I8 -> 0.20759409 | L8: =I8/N8 -> 0.60471408 | M8: =INDEX('Lok Sabha seats'!$E:$E,MATCH(D8,'Lok Sabha seats'!$A:$A,0)) -> 0.057005699 | N8: 364440 | P8: =IF(O8<>"",O8,ROUND(N8*M8/(1+M8),0)) -> 19655 | Q8: =P8/J8 -> 0.42961749 | R8: =IF(P8>J8,"Yes","No") -> No | S8: =IF(P8*L8>J8,"Yes","No") -> No | T8: Wikipedia (reproducing ECI)
A9: 8 | B9: Sindkheda | C9: Dhule | D9: Dhule | E9: BJP | F9: Mahayuti | G9: 151492 | H9: 55608 | I9: 226175 | J9: =G9-H9 -> 95884 | K9: =J9/I9 -> 0.42393722 | L9: =I9/N9 -> 0.66325423 | M9: =INDEX('Lok Sabha seats'!$E:$E,MATCH(D9,'Lok Sabha seats'!$A:$A,0)) -> 0.057005699 | N9: 341008 | P9: =IF(O9<>"",O9,ROUND(N9*M9/(1+M9),0)) -> 18391 | Q9: =P9/J9 -> 0.19180468 | R9: =IF(P9>J9,"Yes","No") -> No | S9: =IF(P9*L9>J9,"Yes","No") -> No | T9: Wikipedia (reproducing ECI)
A10: 9 | B10: Shirpur (ST) | C10: Dhule | D10: Nandurbar | E10: BJP | F10: Mahayuti | G10: 178073 | H10: 32129 | I10: 232168 | J10: =G10-H10 -> 145944 | K10: =J10/I10 -> 0.62861376 | L10: =I10/N10 -> 0.66145483 | M10: =INDEX('Lok Sabha seats'!$E:$E,MATCH(D10,'Lok Sabha seats'!$A:$A,0)) -> 0.034368914 | N10: 350996 | P10: =IF(O10<>"",O10,ROUND(N10*M10/(1+M10),0)) -> 11663 | Q10: =P10/J10 -> 0.079914214 | R10: =IF(P10>J10,"Yes","No") -> No | S10: =IF(P10*L10>J10,"Yes","No") -> No | T10: Wikipedia (reproducing ECI)
A11: 10 | B11: Chopda (ST) | C11: Jalgaon | D11: Raver | E11: SHS | F11: Mahayuti | G11: 122826 | H11: 90513 | I11: 222592 | J11: =G11-H11 -> 32313 | K11: =J11/I11 -> 0.14516694 | L11: =I11/N11 -> 0.67170413 | M11: =INDEX('Lok Sabha seats'!$E:$E,MATCH(D11,'Lok Sabha seats'!$A:$A,0)) -> 0.034691917 | N11: 331384 | P11: =IF(O11<>"",O11,ROUND(N11*M11/(1+M11),0)) -> 11111 | Q11: =P11/J11 -> 0.34385541 | R11: =IF(P11>J11,"Yes","No") -> No | S11: =IF(P11*L11>J11,"Yes","No") -> No | T11: Wikipedia (reproducing ECI)
A12: 11 | B12: Raver | C12: Jalgaon | D12: Raver | E12: BJP | F12: Mahayuti | G12: 113676 | H12: 70114 | I12: 230580 | J12: =G12-H12 -> 43562 | K12: =J12/I12 -> 0.18892358 | L12: =I12/N12 -> 0.74492143 | M12: =INDEX('Lok Sabha seats'!$E:$E,MATCH(D12,'Lok Sabha seats'!$A:$A,0)) -> 0.034691917 | N12: 309536 | P12: =IF(O12<>"",O12,ROUND(N12*M12/(1+M12),0)) -> 10378 | Q12: =P12/J12 -> 0.23823516 | R12: =IF(P12>J12,"Yes","No") -> No | S12: =IF(P12*L12>J12,"Yes","No") -> No | T12: Wikipedia (reproducing ECI)
A13: 12 | B13: Bhusawal (SC) | C13: Jalgaon | D13: Raver | E13: BJP | F13: Mahayuti | G13: 107259 | H13: 59771 | I13: 184294 | J13: =G13-H13 -> 47488 | K13: =J13/I13 -> 0.25767524 | L13: =I13/N13 -> 0.58264281 | M13: =INDEX('Lok Sabha seats'!$E:$E,MATCH(D13,'Lok Sabha seats'!$A:$A,0)) -> 0.034691917 | N13: 316307 | P13: =IF(O13<>"",O13,ROUND(N13*M13/(1+M13),0)) -> 10605 | Q13: =P13/J13 -> 0.22331958 | R13: =IF(P13>J13,"Yes","No") -> No | S13: =IF(P13*L13>J13,"Yes","No") -> No | T13: Wikipedia (reproducing ECI)
... A52: 51 | B52: Umred (SC) | C52: Nagpur | D52: Ramtek | E52: INC | F52: MVA | G52: 85372 | H52: 72547 | I52: 215913 | J52: =G52-H52 -> 12825 | K52: =J52/I52 -> 0.059398925 | L52: =I52/N52 -> 0.71742143 | M52: =INDEX('Lok Sabha seats'!$E:$E,MATCH(D52,'Lok Sabha seats'!$A:$A,0)) -> 0.045824356 | N52: 300957 | P52: =IF(O52<>"",O52,ROUND(N52*M52/(1+M52),0)) -> 13187 | Q52: =P52/J52 -> 1.0282261 | R52: =IF(P52>J52,"Yes","No") -> Yes | S52: =IF(P52*L52>J52,"Yes","No") -> No | T52: Wikipedia (reproducing ECI)
A53: 52 | B53: Nagpur South West | C53: Nagpur | D53: Nagpur | E53: BJP | F53: Mahayuti | G53: 129401 | H53: 89691 | I53: 227498 | J53: =G53-H53 -> 39710 | K53: =J53/I53 -> 0.17455099 | L53: =I53/N53 -> 0.55319873 | M53: =INDEX('Lok Sabha seats'!$E:$E,MATCH(D53,'Lok Sabha seats'!$A:$A,0)) -> 0.071845619 | N53: 411241 | O53: 34833 | P53: =IF(O53<>"",O53,ROUND(N53*M53/(1+M53),0)) -> 34833 | Q53: =P53/J53 -> 0.87718459 | R53: =IF(P53>J53,"Yes","No") -> No | S53: =IF(P53*L53>J53,"Yes","No") -> No | T53: Wikipedia (reproducing ECI)
A54: 53 | B54: Nagpur South | C54: Nagpur | D54: Nagpur | E54: BJP | F54: Mahayuti | G54: 117526 | H54: 101868 | I54: 228294 | J54: =G54-H54 -> 15658 | K54: =J54/I54 -> 0.068586997 | L54: =I54/N54 -> 0.57880205 | M54: =INDEX('Lok Sabha seats'!$E:$E,MATCH(D54,'Lok Sabha seats'!$A:$A,0)) -> 0.071845619 | N54: 394425 | P54: =IF(O54<>"",O54,ROUND(N54*M54/(1+M54),0)) -> 26438 | Q54: =P54/J54 -> 1.688466 | R54: =IF(P54>J54,"Yes","No") -> Yes | S54: =IF(P54*L54>J54,"Yes","No") -> No | T54: Wikipedia (reproducing ECI)
A55: 54 | B55: Nagpur East | C55: Nagpur | D55: Nagpur | E55: BJP | F55: Mahayuti | G55: 163390 | H55: 48102 | I55: 250483 | J55: =G55-H55 -> 115288 | K55: =J55/I55 -> 0.46026277 | L55: =I55/N55 -> 0.59783857 | M55: =INDEX('Lok Sabha seats'!$E:$E,MATCH(D55,'Lok Sabha seats'!$A:$A,0)) -> 0.071845619 | N55: 418981 | P55: =IF(O55<>"",O55,ROUND(N55*M55/(1+M55),0)) -> 28084 | Q55: =P55/J55 -> 0.24359864 | R55: =IF(P55>J55,"Yes","No") -> No | S55: =IF(P55*L55>J55,"Yes","No") -> No | T55: Wikipedia (reproducing ECI)
A56: 55 | B56: Nagpur Central | C56: Nagpur | D56: Nagpur | E56: BJP | F56: Mahayuti | G56: 90560 | H56: 78928 | I56: 196187 | J56: =G56-H56 -> 11632 | K56: =J56/I56 -> 0.059290371 | L56: =I56/N56 -> 0.57504345 | M56: =INDEX('Lok Sabha seats'!$E:$E,MATCH(D56,'Lok Sabha seats'!$A:$A,0)) -> 0.071845619 | N56: 341169 | O56: 25320 | P56: =IF(O56<>"",O56,ROUND(N56*M56/(1+M56),0)) -> 25320 | Q56: =P56/J56 -> 2.1767538 | R56: =IF(P56>J56,"Yes","No") -> Yes | S56: =IF(P56*L56>J56,"Yes","No") -> Yes | T56: Wikipedia (reproducing ECI)
A57: 56 | B57: Nagpur West | C57: Nagpur | D57: Nagpur | E57: INC | F57: MVA | G57: 104144 | H57: 98320 | I57: 219482 | J57: =G57-H57 -> 5824 | K57: =J57/I57 -> 0.026535206 | L57: =I57/N57 -> 0.56516108 | M57: =INDEX('Lok Sabha seats'!$E:$E,MATCH(D57,'Lok Sabha seats'!$A:$A,0)) -> 0.071845619 | N57: 388353 | P57: =IF(O57<>"",O57,ROUND(N57*M57/(1+M57),0)) -> 26031 | Q57: =P57/J57 -> 4.4696085 | R57: =IF(P57>J57,"Yes","No") -> Yes | S57: =IF(P57*L57>J57,"Yes","No") -> Yes | T57: Wikipedia (reproducing ECI)
A58: 57 | B58: Nagpur North (SC) | C58: Nagpur | D58: Nagpur | E58: INC | F58: MVA | G58: 127877 | H58: 99410 | I58: 250641 | J58: =G58-H58 -> 28467 | K58: =J58/I58 -> 0.11357679 | L58: =I58/N58 -> 0.58445592 | M58: =INDEX('Lok Sabha seats'!$E:$E,MATCH(D58,'Lok Sabha seats'!$A:$A,0)) -> 0.071845619 | N58: 428845 | P58: =IF(O58<>"",O58,ROUND(N58*M58/(1+M58),0)) -> 28745 | Q58: =P58/J58 -> 1.0097657 | R58: =IF(P58>J58,"Yes","No") -> Yes | S58: =IF(P58*L58>J58,"Yes","No") -> No | T58: Wikipedia (reproducing ECI)
A59: 58 | B59: Kamthi | C59: Nagpur | D59: Ramtek | E59: BJP | F59: Mahayuti | G59: 174979 | H59: 134033 | I59: 322661 | J59: =G59-H59 -> 40946 | K59: =J59/I59 -> 0.12690099 | L59: =I59/N59 -> 0.64304562 | M59: =INDEX('Lok Sabha seats'!$E:$E,MATCH(D59,'Lok Sabha seats'!$A:$A,0)) -> 0.045824356 | N59: 501770 | P59: =IF(O59<>"",O59,ROUND(N59*M59/(1+M59),0)) -> 21986 | Q59: =P59/J59 -> 0.53695111 | R59: =IF(P59>J59,"Yes","No") -> No | S59: =IF(P59*L59>J59,"Yes","No") -> No | T59: Wikipedia (reproducing ECI)
A60: 59 | B60: Ramtek | C60: Nagpur | D60: Ramtek | E60: SHS | F60: Mahayuti | G60: 107967 | H60: 81412 | I60: 207469 | J60: =G60-H60 -> 26555 | K60: =J60/I60 -> 0.12799503 | L60: =I60/N60 -> 0.72306234 | M60: =INDEX('Lok Sabha seats'!$E:$E,MATCH(D60,'Lok Sabha seats'!$A:$A,0)) -> 0.045824356 | N60: 286931 | P60: =IF(O60<>"",O60,ROUND(N60*M60/(1+M60),0)) -> 12572 | Q60: =P60/J60 -> 0.4734325 | R60: =IF(P60>J60,"Yes","No") -> No | S60: =IF(P60*L60>J60,"Yes","No") -> No | T60: Wikipedia (reproducing ECI)
A61: 60 | B61: Tumsar | C61: Bhandara | D61: Bhandara-Gondiya | E61: NCP | F61: Mahayuti | G61: 135813 | H61: 71508 | I61: 231723 | J61: =G61-H61 -> 64305 | K61: =J61/I61 -> 0.27750806 | L61: =I61/N61 -> 0.74815241 | M61: =INDEX('Lok Sabha seats'!$E:$E,MATCH(D61,'Lok Sabha seats'!$A:$A,0)) -> 0.02478289 | N61: 309727 | P61: =IF(O61<>"",O61,ROUND(N61*M61/(1+M61),0)) -> 7490 | Q61: =P61/J61 -> 0.11647617 | R61: =IF(P61>J61,"Yes","No") -> No | S61: =IF(P61*L61>J61,"Yes","No") -> No | T61: Wikipedia (reproducing ECI)
A62: 61 | B62: Bhandara (SC) | C62: Bhandara | D62: Bhandara-Gondiya | E62: SHS | F62: Mahayuti | G62: 127884 | H62: 89517 | I62: 261950 | J62: =G62-H62 -> 38367 | K62: =J62/I62 -> 0.14646688 | L62: =I62/N62 -> 0.69176876 | M62: =INDEX('Lok Sabha seats'!$E:$E,MATCH(D62,'Lok Sabha seats'!$A:$A,0)) -> 0.02478289 | N62: 378667 | P62: =IF(O62<>"",O62,ROUND(N62*M62/(1+M62),0)) -> 9158 | Q62: =P62/J62 -> 0.23869471 | R62: =IF(P62>J62,"Yes","No") -> No | S62: =IF(P62*L62>J62,"Yes","No") -> No | T62: Wikipedia (reproducing ECI)
A63: 62 | B63: Sakoli | C63: Bhandara | D63: Bhandara-Gondiya | E63: INC | F63: MVA | G63: 96795 | H63: 96587 | I63: 235626 | J63: =G63-H63 -> 208 | K63: =J63/I63 -> 0.00088275487 | L63: =I63/N63 -> 0.71733095 | M63: =INDEX('Lok Sabha seats'!$E:$E,MATCH(D63,'Lok Sabha seats'!$A:$A,0)) -> 0.02478289 | N63: 328476 | P63: =IF(O63<>"",O63,ROUND(N63*M63/(1+M63),0)) -> 7944 | Q63: =P63/J63 -> 38.192308 | R63: =IF(P63>J63,"Yes","No") -> Yes | S63: =IF(P63*L63>J63,"Yes","No") -> Yes | T63: Wikipedia (reproducing ECI)
A64: 63 | B64: Arjuni Morgaon (SC) | C64: Gondia | D64: Bhandara-Gondiya | E64: NCP | F64: Mahayuti | G64: 82506 | H64: 66091 | I64: 183184 | J64: =G64-H64 -> 16415 | K64: =J64/I64 -> 0.089609355 | L64: =I64/N64 -> 0.70736699 | M64: =INDEX('Lok Sabha seats'!$E:$E,MATCH(D64,'Lok Sabha seats'!$A:$A,0)) -> 0.02478289 | N64: 258966 | P64: =IF(O64<>"",O64,ROUND(N64*M64/(1+M64),0)) -> 6263 | Q64: =P64/J64 -> 0.38154127 | R64: =IF(P64>J64,"Yes","No") -> No | S64: =IF(P64*L64>J64,"Yes","No") -> No | T64: Wikipedia (reproducing ECI)
A65: 64 | B65: Tirora | C65: Gondia | D65: Bhandara-Gondiya | E65: BJP | F65: Mahayuti | G65: 102984 | H65: 60298 | I65: 178235 | J65: =G65-H65 -> 42686 | K65: =J65/I65 -> 0.2394928 | L65: =I65/N65 -> 0.65750206 | M65: =INDEX('Lok Sabha seats'!$E:$E,MATCH(D65,'Lok Sabha seats'!$A:$A,0)) -> 0.02478289 | N65: 271079 | P65: =IF(O65<>"",O65,ROUND(N65*M65/(1+M65),0)) -> 6556 | Q65: =P65/J65 -> 0.15358666 | R65: =IF(P65>J65,"Yes","No") -> No | S65: =IF(P65*L65>J65,"Yes","No") -> No | T65: Wikipedia (reproducing ECI)
A66: 65 | B66: Gondiya | C66: Gondia | D66: Bhandara-Gondiya | E66: BJP | F66: Mahayuti | G66: 143012 | H66: 81404 | I66: 233642 | J66: =G66-H66 -> 61608 | K66: =J66/I66 -> 0.26368547 | L66: =I66/N66 -> 0.71767069 | M66: =INDEX('Lok Sabha seats'!$E:$E,MATCH(D66,'Lok Sabha seats'!$A:$A,0)) -> 0.02478289 | N66: 325556 | P66: =IF(O66<>"",O66,ROUND(N66*M66/(1+M66),0)) -> 7873 | Q66: =P66/J66 -> 0.12779185 | R66: =IF(P66>J66,"Yes","No") -> No | S66: =IF(P66*L66>J66,"Yes","No") -> No | T66: Wikipedia (reproducing ECI)
A67: 66 | B67: Amgaon (ST) | C67: Gondia | D67: Gadchiroli-Chimur | E67: BJP | F67: Mahayuti | G67: 110123 | H67: 77402 | I67: 197247 | J67: =G67-H67 -> 32721 | K67: =J67/I67 -> 0.16588845 | L67: =I67/N67 -> 0.73190253 | M67: =INDEX('Lok Sabha seats'!$E:$E,MATCH(D67,'Lok Sabha seats'!$A:$A,0)) -> 0.018698905 | N67: 269499 | P67: =IF(O67<>"",O67,ROUND(N67*M67/(1+M67),0)) -> 4947 | Q67: =P67/J67 -> 0.15118731 | R67: =IF(P67>J67,"Yes","No") -> No | S67: =IF(P67*L67>J67,"Yes","No") -> No | T67: Wikipedia (reproducing ECI)
A68: 67 | B68: Armori (ST) | C68: Gadchiroli | D68: Gadchiroli-Chimur | E68: INC | F68: MVA | G68: 98509 | H68: 92299 | I68: 203279 | J68: =G68-H68 -> 6210 | K68: =J68/I68 -> 0.030549147 | L68: =I68/N68 -> 0.77359754 | M68: =INDEX('Lok Sabha seats'!$E:$E,MATCH(D68,'Lok Sabha seats'!$A:$A,0)) -> 0.018698905 | N68: 262771 | P68: =IF(O68<>"",O68,ROUND(N68*M68/(1+M68),0)) -> 4823 | Q68: =P68/J68 -> 0.77665056 | R68: =IF(P68>J68,"Yes","No") -> No | S68: =IF(P68*L68>J68,"Yes","No") -> No | T68: Wikipedia (reproducing ECI)
... A138: 137 | B138: Bhiwandi East | C138: Thane | D138: Bhiwandi | E138: SP | F138: Other | G138: 119687 | H138: 67672 | I138: 191683 | J138: =G138-H138 -> 52015 | K138: =J138/I138 -> 0.27135948 | L138: =I138/N138 -> 0.51300834 | M138: =INDEX('Lok Sabha seats'!$E:$E,MATCH(D138,'Lok Sabha seats'!$A:$A,0)) -> 0.076580888 | N138: 373645 | P138: =IF(O138<>"",O138,ROUND(N138*M138/(1+M138),0)) -> 26579 | Q138: =P138/J138 -> 0.51098722 | R138: =IF(P138>J138,"Yes","No") -> No | S138: =IF(P138*L138>J138,"Yes","No") -> No | T138: Wikipedia (reproducing ECI)
A139: 138 | B139: Kalyan West | C139: Thane | D139: Bhiwandi | E139: SHS | F139: Mahayuti | G139: 126020 | H139: 83566 | I139: 245557 | J139: =G139-H139 -> 42454 | K139: =J139/I139 -> 0.17288858 | L139: =I139/N139 -> 0.5573279 | M139: =INDEX('Lok Sabha seats'!$E:$E,MATCH(D139,'Lok Sabha seats'!$A:$A,0)) -> 0.076580888 | N139: 440597 | O139: 40459 | P139: =IF(O139<>"",O139,ROUND(N139*M139/(1+M139),0)) -> 40459 | Q139: =P139/J139 -> 0.95300796 | R139: =IF(P139>J139,"Yes","No") -> No | S139: =IF(P139*L139>J139,"Yes","No") -> No | T139: Wikipedia (reproducing ECI)
A140: 139 | B140: Murbad | C140: Thane | D140: Bhiwandi | E140: BJP | F140: Mahayuti | G140: 175509 | H140: 123117 | I140: 318875 | J140: =G140-H140 -> 52392 | K140: =J140/I140 -> 0.16430263 | L140: =I140/N140 -> 0.67839971 | M140: =INDEX('Lok Sabha seats'!$E:$E,MATCH(D140,'Lok Sabha seats'!$A:$A,0)) -> 0.076580888 | N140: 470040 | P140: =IF(O140<>"",O140,ROUND(N140*M140/(1+M140),0)) -> 33436 | Q140: =P140/J140 -> 0.63818904 | R140: =IF(P140>J140,"Yes","No") -> No | S140: =IF(P140*L140>J140,"Yes","No") -> No | T140: Wikipedia (reproducing ECI)
A141: 140 | B141: Ambarnath (SC) | C141: Thane | D141: Kalyan | E141: SHS | F141: Mahayuti | G141: 111368 | H141: 59993 | I141: 184506 | J141: =G141-H141 -> 51375 | K141: =J141/I141 -> 0.27844623 | L141: =I141/N141 -> 0.49245724 | M141: =INDEX('Lok Sabha seats'!$E:$E,MATCH(D141,'Lok Sabha seats'!$A:$A,0)) -> 0.10262503 | N141: 374664 | P141: =IF(O141<>"",O141,ROUND(N141*M141/(1+M141),0)) -> 34871 | Q141: =P141/J141 -> 0.67875426 | R141: =IF(P141>J141,"Yes","No") -> No | S141: =IF(P141*L141>J141,"Yes","No") -> No | T141: Wikipedia (reproducing ECI)
A142: 141 | B142: Ulhasnagar | C142: Thane | D142: Kalyan | E142: BJP | F142: Mahayuti | G142: 82231 | H142: 51477 | I142: 155211 | J142: =G142-H142 -> 30754 | K142: =J142/I142 -> 0.19814317 | L142: =I142/N142 -> 0.54771525 | M142: =INDEX('Lok Sabha seats'!$E:$E,MATCH(D142,'Lok Sabha seats'!$A:$A,0)) -> 0.10262503 | N142: 283379 | P142: =IF(O142<>"",O142,ROUND(N142*M142/(1+M142),0)) -> 26375 | Q142: =P142/J142 -> 0.85761202 | R142: =IF(P142>J142,"Yes","No") -> No | S142: =IF(P142*L142>J142,"Yes","No") -> No | T142: Wikipedia (reproducing ECI)
A143: 142 | B143: Kalyan East | C143: Thane | D143: Kalyan | E143: BJP | F143: Mahayuti | G143: 81516 | H143: 55108 | I143: 193395 | J143: =G143-H143 -> 26408 | K143: =J143/I143 -> 0.13654955 | L143: =I143/N143 -> 0.58751781 | M143: =INDEX('Lok Sabha seats'!$E:$E,MATCH(D143,'Lok Sabha seats'!$A:$A,0)) -> 0.10262503 | N143: 329173 | O143: 29793 | P143: =IF(O143<>"",O143,ROUND(N143*M143/(1+M143),0)) -> 29793 | Q143: =P143/J143 -> 1.1281809 | R143: =IF(P143>J143,"Yes","No") -> Yes | S143: =IF(P143*L143>J143,"Yes","No") -> No | T143: Wikipedia (reproducing ECI)
A144: 143 | B144: Dombivali | C144: Thane | D144: Kalyan | E144: BJP | F144: Mahayuti | G144: 123815 | H144: 46709 | I144: 176526 | J144: =G144-H144 -> 77106 | K144: =J144/I144 -> 0.43679685 | L144: =I144/N144 -> 0.56376109 | M144: =INDEX('Lok Sabha seats'!$E:$E,MATCH(D144,'Lok Sabha seats'!$A:$A,0)) -> 0.10262503 | N144: 313122 | O144: 38012 | P144: =IF(O144<>"",O144,ROUND(N144*M144/(1+M144),0)) -> 38012 | Q144: =P144/J144 -> 0.49298368 | R144: =IF(P144>J144,"Yes","No") -> No | S144: =IF(P144*L144>J144,"Yes","No") -> No | T144: Wikipedia (reproducing ECI)
A145: 144 | B145: Kalyan Rural | C145: Thane | D145: Kalyan | E145: SHS | F145: Mahayuti | G145: 141164 | H145: 74768 | I145: 296065 | J145: =G145-H145 -> 66396 | K145: =J145/I145 -> 0.22426156 | L145: =I145/N145 -> 0.58023859 | M145: =INDEX('Lok Sabha seats'!$E:$E,MATCH(D145,'Lok Sabha seats'!$A:$A,0)) -> 0.10262503 | N145: 510247 | P145: =IF(O145<>"",O145,ROUND(N145*M145/(1+M145),0)) -> 47490 | Q145: =P145/J145 -> 0.71525393 | R145: =IF(P145>J145,"Yes","No") -> No | S145: =IF(P145*L145>J145,"Yes","No") -> No | T145: Wikipedia (reproducing ECI)
A146: 145 | B146: Mira Bhayandar | C146: Thane | D146: Thane | E146: BJP | F146: Mahayuti | G146: 144376 | H146: 83943 | I146: 263124 | J146: =G146-H146 -> 60433 | K146: =J146/I146 -> 0.22967498 | L146: =I146/N146 -> 0.51505886 | M146: =INDEX('Lok Sabha seats'!$E:$E,MATCH(D146,'Lok Sabha seats'!$A:$A,0)) -> 0.071377921 | N146: 510862 | P146: =IF(O146<>"",O146,ROUND(N146*M146/(1+M146),0)) -> 34035 | Q146: =P146/J146 -> 0.56318568 | R146: =IF(P146>J146,"Yes","No") -> No | S146: =IF(P146*L146>J146,"Yes","No") -> No | T146: Wikipedia (reproducing ECI)
A147: 146 | B147: Ovala-Majiwada | C147: Thane | D147: Thane | E147: SHS | F147: Mahayuti | G147: 184178 | H147: 76020 | I147: 285547 | J147: =G147-H147 -> 108158 | K147: =J147/I147 -> 0.37877477 | L147: =I147/N147 -> 0.52383372 | M147: =INDEX('Lok Sabha seats'!$E:$E,MATCH(D147,'Lok Sabha seats'!$A:$A,0)) -> 0.071377921 | N147: 545110 | P147: =IF(O147<>"",O147,ROUND(N147*M147/(1+M147),0)) -> 36317 | Q147: =P147/J147 -> 0.33577729 | R147: =IF(P147>J147,"Yes","No") -> No | S147: =IF(P147*L147>J147,"Yes","No") -> No | T147: Wikipedia (reproducing ECI)
...

Sheet Notes & sources
A1: Maharashtra voter-roll check, 2024 (prepared 11 Oct 2026)
A3: Colour key: blue = hardcoded source data; black = formula; green = formula pulling from another sheet.
A5: Definitions
A6: Margin = winner votes − runner-up votes. Margin % = margin ÷ total votes polled (incl. NOTA).
A7: Lok Sabha seat elector growth % = (sum of its 6 assembly seats' general electors on 30 Oct 2024 − LS May 2024 electors) ÷ LS May 2024 electors.
A8: Voters added (used) = actual RTI net addition where available (5 seats); otherwise Electors 30 Oct 2024 × g ÷ (1+g), applying the Lok Sabha seat growth rate g to each of its assembly seats.
A9: Alliance: Mahayuti = BJP, Shiv Sena (SHS), NCP. MVA = INC, Shiv Sena (UBT), NCP (SP). Others = all remaining winners.
A11: Limitations
A12: Official Lok Sabha 2024 electors per assembly segment were not retrievable; 283 of 288 "voters added" values are estimates.
A13: Net additions are not votes. Added voters did not all vote, nor all for the winner. A "Yes" flags seats where additions were large enough to matter, not seats they decided.
A15: Sources
A16: Lok Sabha 2024 electors by seat: ECI voter-turnout data, phases 1–5 — https://data.opencity.in/dataset/parliament-elections-2024-voter-turnout (source: eci.gov.in)
... A21: Assembly-to-Lok-Sabha mapping: Delimitation of Parliamentary and Assembly Constituencies Order, 2008.
